Workbook

Sheet Messages
A1: Message | B1: Kind | C1: From → To | D1: When it is sent | E1: Fields
A2: RxReport envelope | B2: Envelope | C2: Vehicle → OCS → RoboCommand | D2: Wraps every report | E2: =COUNTIF(Fields!$A:$A,$A2)
A3: RxCommand envelope | B3: Envelope | C3: RoboCommand → OCS → Vehicle | D3: Wraps every command | E3: =COUNTIF(Fields!$A:$A,$A3)
A4: RxRequest envelope | B4: Envelope | C4: OCS → RoboCommand | D4: Wraps every request | E4: =COUNTIF(Fields!$A:$A,$A4)
A5: Heartbeat | B5: Report body | C5: Every vehicle → OCS → RoboCommand | D5: Twice a second, continuously | E5: =COUNTIF(Fields!$A:$A,$A5)
A6: SafePassageReport | B6: Report body | C6: USV/UUV (Core) or UAV (Adv) → OCS → RC | D6: Task 1 — whenever detection changes | E6: =COUNTIF(Fields!$A:$A,$A6)
A7: BuoyDetection | B7: Repeated element | C7: (inside SafePassageReport) | D7: One per buoy detected | E7: =COUNTIF(Fields!$A:$A,$A7)
A8: PipelineSurveyReport | B8: Report body | C8: UUV → USV → OCS → RC | D8: Task 2 — once, normally on surfacing | E8: =COUNTIF(Fields!$A:$A,$A8)
A9: ResourceDeliveryRequest | B9: Report body | C9: Whichever vehicle reads the code → OCS → RC | D9: Tasks 2 & 3 — on reading the light code | E9: =COUNTIF(Fields!$A:$A,$A9)
A10: DockingReport | B10: Report body | C10: USV → OCS → RC | D10: Task 3 — on docking | E10: =COUNTIF(Fields!$A:$A,$A10)
A11: FirefightingReport | B11: Report body | C11: USV → OCS → RC | D11: Task 3 — on extinguishing | E11: =COUNTIF(Fields!$A:$A,$A11)
A12: IncidentAck | B12: Report body | C12: Targeted vehicle → OCS → RC | D12: Task 4 — immediately on any command | E12: =COUNTIF(Fields!$A:$A,$A12)
A13: ReadinessReport | B13: Report body | C13: Targeted vehicle → OCS → RC | D13: Task 4 — on reaching station | E13: =COUNTIF(Fields!$A:$A,$A13)
... A22: LatLng | B22: Shared type | C22: (inside any position field) | D22: Wherever a position appears | E22: =COUNTIF(Fields!$A:$A,$A22)

Sheet Fields
A1: Message | B1: Kind | C1: Field | D1: Type | E1: Repeated | F1: Applies to | G1: Units / range | H1: What it holds | I1: Our encoding (fill in) | J1: Bits (fill in)
A2: RxReport envelope | B2: Envelope | C2: team_id | D2: text | F2: All | H2: Our team identifier, e.g. ASTA. Constant for the whole competition.
A3: RxReport envelope | B3: Envelope | C3: vehicle_id | D3: text | F3: All | H3: Which vehicle the report is ABOUT, not which machine sent it. Graey's reports say Graey even though Crusader carries them.
A4: RxReport envelope | B4: Envelope | C4: seq | D4: whole number | F4: All | G4: increases by 1 | H4: Counted separately for each vehicle. Graey's counter is its own, not shared with Crusader's, and must never go backwards.
A5: RxReport envelope | B5: Envelope | C5: sent_at | D5: timestamp | F5: All | H5: When it was sent. The OCS re-stamps this from its own clock before publishing onward, so a vehicle's value is used only to measure staleness.
A6: RxReport envelope | B6: Envelope | C6: body | D6: one of 8 | F6: All | H6: Exactly one of: heartbeat, safe_passage, pipeline_survey, resource_delivery, docking, firefighting, incident_ack, readiness
A7: RxCommand envelope | B7: Envelope | C7: team_id | D7: text | F7: All | H7: The team being addressed.
A8: RxCommand envelope | B8: Envelope | C8: seq | D8: whole number | F8: All | G8: increases by 1 | H8: Command counter.
A9: RxCommand envelope | B9: Envelope | C9: sent_at | D9: timestamp | F9: All | H9: When RoboCommand sent it.
A10: RxCommand envelope | B10: Envelope | C10: vehicle_id | D10: text | F10: All | G10: optional | H10: Which vehicle to address. Left empty, it applies to every vehicle of the type named in the body — for 2026 that is exactly one vehicle per type.
A11: RxCommand envelope | B11: Envelope | C11: body | D11: one of 6 | F11: All | H11: Exactly one of: run_start, assistance_request, keep_out_zone, all_clear, moving_object_alert, readiness_confirm
A12: RxRequest envelope | B12: Envelope | C12: team_id | D12: text | F12: All | H12: Our team identifier.
A13: RxRequest envelope | B13: Envelope | C13: seq | D13: whole number | F13: All | G13: increases by 1 | H13: Request counter.
A14: RxRequest envelope | B14: Envelope | C14: sent_at | D14: timestamp | F14: All | H14: When the OCS sent it.
A15: RxRequest envelope | B15: Envelope | C15: body | D15: one of 1 | F15: All | H15: Exactly one of: run_declaration
A16: Heartbeat | B16: Report body | C16: state | D16: choice (4) | F16: All | G16: 4 choices | H16: Killed, manual, or autonomous. Every declared vehicle must reach autonomous before the run can start.
A17: Heartbeat | B17: Report body | C17: position | D17: position | F17: All | H17: Where the vehicle is.
A18: Heartbeat | B18: Report body | C18: spd_mps | D18: decimal | F18: All | G18: metres/second | H18: Speed over ground.
A19: Heartbeat | B19: Report body | C19: heading_deg | D19: decimal | F19: All | G19: degrees, 0 = true north | H19: Heading, increasing clockwise. Goes not-a-number when GPS yaw is unresolved — that is deliberate, not a fault to scrub.
A20: Heartbeat | B20: Report body | C20: roll_deg | D20: decimal | F20: All | G20: degrees | H20: Roll angle.
A21: Heartbeat | B21: Report body | C21: pitch_deg | D21: decimal | F21: All | G21: degrees | H21: Pitch angle.
A22: Heartbeat | B22: Report body | C22: altitude_hae_m | D22: decimal | F22: UAV mainly | G22: metres | H22: Height above the ellipsoid. NOT height above sea level.
A23: Heartbeat | B23: Report body | C23: depth_m | D23: decimal | F23: UUV only | G23: metres | H23: Depth below the surface.
A24: Heartbeat | B24: Report body | C24: current_task | D24: choice (6) | F24: All | G24: 6 choices | H24: Which task the vehicle believes it is executing. This is how RoboCommand decides an attempt has started or ended.
A25: Heartbeat | B25: Report body | C25: vehicle_type | D25: choice (4) | F25: All | G25: 4 choices | H25: Surface, underwater or air. A UUV stays UUV even while surfaced.
A26: Heartbeat | B26: Report body | C26: flight_phase | D26: choice (3) | F26: UAV only | G26: 3 choices | H26: On the ground or airborne. Surface and underwater vehicles leave it unset.
A27: SafePassageReport | B27: Report body | C27: entry_position | D27: position | F27: USV/UUV/UAV | H27: Where the flashing blue entry buoy is.
A28: SafePassageReport | B28: Report body | C28: exit_position | D28: position | F28: USV/UUV/UAV | H28: Where the steady blue exit buoy is.
A29: SafePassageReport | B29: Report body | C29: buoys | D29: BuoyDetection | E29: yes | F29: USV/UUV/UAV | G29: 10 expected | H29: Every buoy detected. See BuoyDetection for what each entry holds.
A30: BuoyDetection | B30: Repeated element | C30: position | D30: position | F30: USV/UUV/UAV | H30: Where that buoy is.
A31: BuoyDetection | B31: Repeated element | C31: state | D31: choice (6) | F31: USV/UUV/UAV | G31: 6 choices | H31: What its light is doing — this is what tells the boat which side to pass.
A32: PipelineSurveyReport | B32: Report body | C32: active_buoy_position | D32: position | F32: UUV | H32: Where the active green buoy is: the pinger end, and the end the segment list is ordered from.
A33: PipelineSurveyReport | B33: Report body | C33: segments | D33: choice (3) | E33: yes | F33: UUV | G33: 3 choices each | H33: Each segment intact or damaged, in order from the active buoy. Order carries the meaning; there is no per-segment position.
A34: ResourceDeliveryRequest | B34: Report body | C34: task | D34: choice (6) | F34: UUV/UAV | G34: 6 choices | H34: Which task this delivery belongs to.
A35: ResourceDeliveryRequest | B35: Report body | C35: resource_color | D35: choice (5) | F35: UUV/UAV | G35: 5 choices | H35: Which colour tin is required. 'Any' at Advanced tier, a specific colour at Disruptive.
A36: ResourceDeliveryRequest | B36: Report body | C36: delivery_circle_color | D36: choice (5) | F36: UUV/UAV | G36: 5 choices | H36: Which colour circle on the platform it must go to. Field order matches the flash order.
A37: DockingReport | B37: Report body | C37: bay_id | D37: whole number | F37: USV | G37: 1 to 3 | H37: Which bay was docked in.
A38: FirefightingReport | B38: Report body | C38: window_id | D38: whole number | F38: USV | H38: Which window the fire was put out at.
A39: IncidentAck | B39: Report body | C39: command_seq | D39: whole number | F39: Whichever was targeted | H39: Sequence number of the command being acknowledged.
A40: ReadinessReport | B40: Report body | C40: command_seq | D40: whole number | F40: Whichever was targeted | H40: Sequence number of the assistance request now reached.
...

Sheet Choice lists
A1: Choice list | B1: Value | C1: Name | D1: Meaning | E1: Values in list
A2: RobotState | B2: 0 | C2: STATE_UNKNOWN | D2: Never send. This is what an unset field looks like. | E2: =COUNTIF($A:$A,$A2)
A3: RobotState | B3: 1 | C3: STATE_KILLED | D3: Emergency stop is active. | E3: =COUNTIF($A:$A,$A3)
A4: RobotState | B4: 2 | C4: STATE_MANUAL | D4: Under human control. | E4: =COUNTIF($A:$A,$A4)
A5: RobotState | B5: 3 | C5: STATE_AUTO | D5: Driving itself. Every declared vehicle must reach this before the run can start. | E5: =COUNTIF($A:$A,$A5)
A6: TaskTier | B6: 0 | C6: TIER_UNKNOWN | D6: Never send. | E6: =COUNTIF($A:$A,$A6)
A7: TaskTier | B7: 1 | C7: TIER_NONE | D7: Not attempting this task. | E7: =COUNTIF($A:$A,$A7)
A8: TaskTier | B8: 2 | C8: TIER_CORE | D8: Base requirements only. | E8: =COUNTIF($A:$A,$A8)
A9: TaskTier | B9: 3 | C9: TIER_ADVANCED | D9: Core plus advanced. | E9: =COUNTIF($A:$A,$A9)
A10: TaskTier | B10: 4 | C10: TIER_DISRUPTIVE | D10: Core plus advanced plus disruptive. | E10: =COUNTIF($A:$A,$A10)
A11: BeaconState | B11: 0 | C11: BEACON_STATE_UNKNOWN | D11: Never send. | E11: =COUNTIF($A:$A,$A11)
A12: BeaconState | B12: 1 | C12: BEACON_STATE_OFF | D12: Not part of the safe route. | E12: =COUNTIF($A:$A,$A12)
A13: BeaconState | B13: 2 | C13: BEACON_STATE_FLASHING_RED | D13: Pass on the starboard side. | E13: =COUNTIF($A:$A,$A13)
... A17: Color | B17: 0 | C17: COLOR_UNKNOWN | D17: Never send. | E17: =COUNTIF($A:$A,$A17)
A18: Color | B18: 1 | C18: COLOR_RED | E18: =COUNTIF($A:$A,$A18)
A19: Color | B19: 2 | C19: COLOR_GREEN | E19: =COUNTIF($A:$A,$A19)
A20: Color | B20: 3 | C20: COLOR_BLUE | E20: =COUNTIF($A:$A,$A20)
A21: Color | B21: 4 | C21: COLOR_ANY | D21: Any tin is acceptable. Used at Advanced tier. | E21: =COUNTIF($A:$A,$A21)
A22: FlightPhase | B22: 0 | C22: FLIGHT_PHASE_UNKNOWN | D22: Never send from Ekko. Surface and underwater vehicles leave it here. | E22: =COUNTIF($A:$A,$A22)
A23: FlightPhase | B23: 1 | C23: FLIGHT_PHASE_GROUNDED | D23: On the ground. | E23: =COUNTIF($A:$A,$A23)
A24: FlightPhase | B24: 2 | C24: FLIGHT_PHASE_AIRBORNE | D24: In flight. | E24: =COUNTIF($A:$A,$A24)
A25: PipelineSegmentStatus | B25: 0 | C25: PIPELINE_SEGMENT_UNKNOWN | D25: Never send. | E25: =COUNTIF($A:$A,$A25)
A26: PipelineSegmentStatus | B26: 1 | C26: PIPELINE_SEGMENT_INTACT | D26: Green light — functional. | E26: =COUNTIF($A:$A,$A26)
A27: PipelineSegmentStatus | B27: 2 | C27: PIPELINE_SEGMENT_DAMAGED | D27: Red light — needs repair. | E27: =COUNTIF($A:$A,$A27)
A28: RxTask | B28: 0 | C28: TASK_UNKNOWN | D28: Never send. NOT a stand-down signal — it also appears during a mode change. | E28: =COUNTIF($A:$A,$A28)
A29: RxTask | B29: 1 | C29: TASK_NONE | D29: Deliberately idle. This is how a vehicle stands down from a task. | E29: =COUNTIF($A:$A,$A29)
A30: RxTask | B30: 2 | C30: TASK_SAFE_PASSAGE | D30: Task 1. | E30: =COUNTIF($A:$A,$A30)
A31: RxTask | B31: 3 | C31: TASK_INFRA_SURVEY_REPAIR | D31: Task 2. | E31: =COUNTIF($A:$A,$A31)
A32: RxTask | B32: 4 | C32: TASK_COORDINATED_LOGISTICS | D32: Task 3. | E32: =COUNTIF($A:$A,$A32)
... A37: VehicleType | B37: 3 | C37: TYPE_UAV | D37: Ekko. | E37: =COUNTIF($A:$A,$A37)

Sheet Encoding rules
A1: What any custom encoding must still preserve
A2: Any format is allowed between our own vehicles — RoboNation specifies nothing there. But the OCS has to rebuild a valid report from whatever arrives, so these four must survive whatever compression is applied.
A4: Rule | B4: Why | C4: What it means for a packed format
A5: Attribution survives | B5: A report about Graey stays about Graey. Crusader carries it; it does not restate it as its own. | C5: If the vehicle id is dropped because the modem address already implies it, the OCS must put it back.
A6: Sequence counting is per vehicle | B6: Graey's reports are counted on Graey's own counter, separate from Crusader's, and it must never go backwards. | C6: A shortened counter on the wire is fine, but the OCS has to expand it into one that keeps increasing across the whole run.
A7: No UNKNOWN values | B7: Every choice list has an UNKNOWN at zero and none may be sent. A field left out decodes as UNKNOWN. | C7: Any field the compact format omits needs a defined substitute at the OCS — or the report must not be sent.
A8: Absent is not zero | B8: An invented value is indistinguishable from a real one and is scored as though the vehicle were somewhere it is not. | C8: Where the truth cannot be represented, send nothing and let the gap show. A gap is visible; a fabricated number is not.
A10: Field names, types and choice lists read directly from robonation/robocommand, RobotX_2026/proto, revision f6457fa (6 August 2026). Encoding and message sizing are deliberately out of scope.
