Workbook

Sheet Messages
A1: Message | B1: Kind | C1: From → To | D1: When it is sent | E1: Fields
A2: RxReport envelope | B2: Envelope | C2: Vehicle → OCS → RoboCommand | D2: Wraps every report | E2: =COUNTIF(Fields!$A:$A,$A2) -> 0
A3: RxCommand envelope | B3: Envelope | C3: RoboCommand → OCS → Vehicle | D3: Wraps every command | E3: =COUNTIF(Fields!$A:$A,$A3) -> 0
A4: RxRequest envelope | B4: Envelope | C4: OCS → RoboCommand | D4: Wraps every request | E4: =COUNTIF(Fields!$A:$A,$A4) -> 0
A5: Heartbeat | B5: Report body | C5: Every vehicle → OCS → RoboCommand | D5: Twice a second, continuously | E5: =COUNTIF(Fields!$A:$A,$A5) -> 11
A6: SafePassageReport | B6: Report body | C6: USV/UUV (Core) or UAV (Adv) → OCS → RC | D6: Task 1 — whenever detection changes | E6: =COUNTIF(Fields!$A:$A,$A6) -> 3
A7: BuoyDetection | B7: Repeated element | C7: (inside SafePassageReport) | D7: One per buoy detected | E7: =COUNTIF(Fields!$A:$A,$A7) -> 2
A8: PipelineSurveyReport | B8: Report body | C8: UUV → USV → OCS → RC | D8: Task 2 — once, normally on surfacing | E8: =COUNTIF(Fields!$A:$A,$A8) -> 2
A9: ResourceDeliveryRequest | B9: Report body | C9: Whichever vehicle reads the code → OCS → RC | D9: Tasks 2 & 3 — on reading the light code | E9: =COUNTIF(Fields!$A:$A,$A9) -> 3
A10: DockingReport | B10: Report body | C10: USV → OCS → RC | D10: Task 3 — on docking | E10: =COUNTIF(Fields!$A:$A,$A10) -> 1
A11: FirefightingReport | B11: Report body | C11: USV → OCS → RC | D11: Task 3 — on extinguishing | E11: =COUNTIF(Fields!$A:$A,$A11) -> 1
A12: IncidentAck | B12: Report body | C12: Targeted vehicle → OCS → RC | D12: Task 4 — immediately on any command | E12: =COUNTIF(Fields!$A:$A,$A12) -> 1
A13: ReadinessReport | B13: Report body | C13: Targeted vehicle → OCS → RC | D13: Task 4 — on reaching station | E13: =COUNTIF(Fields!$A:$A,$A13) -> 1
... A22: LatLng | B22: Shared type | C22: (inside any position field) | D22: Wherever a position appears | E22: =COUNTIF(Fields!$A:$A,$A22) -> 2

Sheet Fields
A1: Message | B1: Kind | C1: Field | D1: Type | E1: Repeated | F1: Used for Inter-Vehicle Comms | G1: Applies to | H1: Units / range | I1: What it holds | J1: Our encoding (fill in) | K1: Bits (fill in)
A2: Mandatory Msg (2hz)
A3: Heartbeat | B3: Report body | C3: state | D3: choice (4) | G3: All | H3: 4 choices | I3: Killed, manual, or autonomous. Every declared vehicle must reach autonomous before the run can start.
A4: Heartbeat | B4: Report body | C4: position | D4: position | G4: All | I4: Where the vehicle is.
A5: Heartbeat | B5: Report body | C5: spd_mps | D5: decimal | G5: All | H5: metres/second | I5: Speed over ground.
A6: Heartbeat | B6: Report body | C6: heading_deg | D6: decimal | G6: All | H6: degrees, 0 = true north | I6: Heading, increasing clockwise. Goes not-a-number when GPS yaw is unresolved — that is deliberate, not a fault to scrub.
A7: Heartbeat | B7: Report body | C7: roll_deg | D7: decimal | G7: All | H7: degrees | I7: Roll angle.
A8: Heartbeat | B8: Report body | C8: pitch_deg | D8: decimal | G8: All | H8: degrees | I8: Pitch angle.
A9: Heartbeat | B9: Report body | C9: altitude_hae_m | D9: decimal | G9: UAV mainly | H9: metres | I9: Height above the ellipsoid. NOT height above sea level.
A10: Heartbeat | B10: Report body | C10: depth_m | D10: decimal | G10: UUV only | H10: metres | I10: Depth below the surface.
A11: Heartbeat | B11: Report body | C11: current_task | D11: choice (6) | G11: All | H11: 6 choices | I11: Which task the vehicle believes it is executing. This is how RoboCommand decides an attempt has started or ended.
A12: Heartbeat | B12: Report body | C12: vehicle_type | D12: choice (4) | G12: All | H12: 4 choices | I12: Surface, underwater or air. A UUV stays UUV even while surfaced.
A13: Heartbeat | B13: Report body | C13: flight_phase | D13: choice (3) | G13: UAV only | H13: 3 choices | I13: On the ground or airborne. Surface and underwater vehicles leave it unset.
A14: Mission related MSG
A15: SafePassageReport | B15: Report body | C15: entry_position | D15: position | G15: USV/UUV/UAV | I15: Where the flashing blue entry buoy is.
A16: SafePassageReport | B16: Report body | C16: exit_position | D16: position | G16: USV/UUV/UAV | I16: Where the steady blue exit buoy is.
A17: SafePassageReport | B17: Report body | C17: buoys | D17: BuoyDetection | E17: yes | G17: USV/UUV/UAV | H17: 10 expected | I17: Every buoy detected. See BuoyDetection for what each entry holds.
A18: BuoyDetection | B18: Repeated element | C18: position | D18: position | F18: UAV --> USV | G18: USV/UUV/UAV | I18: Where that buoy is.
A19: BuoyDetection | B19: Repeated element | C19: state | D19: choice (6) | F19: UAV --> USV | G19: USV/UUV/UAV | H19: 6 choices | I19: What its light is doing — this is what tells the boat which side to pass.
A20: USVReached Buoy gate | B20: Custom Inter-Vehicle MSG | C20: Reached | D20: Trigger | E20: yes | F20: USV --> UAV | G20: UAV/USV | H20: Trigger | I20: When the USV reach one set of buoys, USV tells UAV to check the next set of buoys
A21: NextBuoySet | B21: Custom Inter-Vehicle MSG | C21: [id_1, id_2] Buoy ID | D21: ID | E21: yes | F21: UAV --> USV | G21: UAV/USV | H21: N/A | I21: UAV tell USV the next pair of red green buoy ids
A22: PipelineSurveyReport | B22: Report body | C22: active_buoy_position | D22: position | F22: USV --> UUV | G22: UUV | I22: Where the active green buoy is: the pinger end, and the end the segment list is ordered from.
A23: PipelineSurveyReport | B23: Report body | C23: segments | D23: choice (3) | E23: yes | F23: UUV --> USV | G23: UUV | H23: 3 choices each | I23: Each segment intact or damaged, in order from the active buoy. Order carries the meaning; there is no per-segment position.
A24: ResourceDeliveryRequest | B24: Report body | C24: task | D24: choice (6) | G24: UUV/UAV | H24: 6 choices | I24: Which task this delivery belongs to.
A25: ResourceDeliveryRequest | B25: Report body | C25: resource_color | D25: choice (5) | F25: USV --> UAV | G25: UUV/UAV | H25: 5 choices | I25: Which colour tin is required. 'Any' at Advanced tier, a specific colour at Disruptive.
A26: ResourceDeliveryRequest | B26: Report body | C26: delivery_circle_color | D26: choice (5) | F26: USV --> UAV | G26: UUV/UAV | H26: 5 choices | I26: Which colour circle on the platform it must go to. Field order matches the flash order.
A27: DockingReport | B27: Report body | C27: bay_id | D27: whole number | G27: USV | H27: 1 to 3 | I27: Which bay was docked in.
A28: FirefightingReport | B28: Report body | C28: window_id | D28: whole number | G28: USV | I28: Which window the fire was put out at.
A29: IncidentAck | B29: Report body | C29: command_seq | D29: whole number | G29: Whichever was targeted | I29: Sequence number of the command being acknowledged.
A30: ReadinessReport | B30: Report body | C30: command_seq | D30: whole number | G30: Whichever was targeted | I30: Sequence number of the assistance request now reached.
A31: Msg OCS <--> RoboCommand
A32: RunStart | B32: Command body | C32: declaration_seq | D32: whole number | G32: — | I32: Which run declaration this answers. The OCS must check it matches the one it sent.
A33: RunStart | B33: Command body | C33: run_id | D33: whole number | G33: — | I33: Identifier assigned to this run.
A34: AssistanceRequest | B34: Command body | C34: position | D34: position | G34: Named type | I34: Where to transit to and loiter.
A35: AssistanceRequest | B35: Command body | C35: vehicle_type | D35: choice (4) | G35: Named type | H35: 4 choices | I35: Which class of vehicle is being asked.
A36: KeepOutZone | B36: Command body | C36: center | D36: position | G36: Named type | I36: Centre of the zone.
A37: KeepOutZone | B37: Command body | C37: radius_m | D37: decimal | G37: Named type | H37: metres | I37: Radius from that centre.
A38: KeepOutZone | B38: Command body | C38: vehicle_type | D38: choice (4) | G38: Named type | H38: 4 choices | I38: Which class must stay out.
A39: AllClear | B39: Command body | C39: vehicle_type | D39: choice (4) | G39: Named type | H39: 4 choices | I39: Which class may resume normal operations.
A40: MovingObjectAlert | B40: Command body | C40: position | D40: position | G40: Affected types | I40: Where the moving object is.
...

Sheet Choice lists
A1: Choice list | B1: Value | C1: Name | D1: Meaning | E1: Values in list
A2: RobotState | B2: 0 | C2: STATE_UNKNOWN | D2: Never send. This is what an unset field looks like. | E2: =COUNTIF($A:$A,$A2) -> 4
A3: RobotState | B3: 1 | C3: STATE_KILLED | D3: Emergency stop is active. | E3: =COUNTIF($A:$A,$A3) -> 4
A4: RobotState | B4: 2 | C4: STATE_MANUAL | D4: Under human control. | E4: =COUNTIF($A:$A,$A4) -> 4
A5: RobotState | B5: 3 | C5: STATE_AUTO | D5: Driving itself. Every declared vehicle must reach this before the run can start. | E5: =COUNTIF($A:$A,$A5) -> 4
A6: TaskTier | B6: 0 | C6: TIER_UNKNOWN | D6: Never send. | E6: =COUNTIF($A:$A,$A6) -> 5
A7: TaskTier | B7: 1 | C7: TIER_NONE | D7: Not attempting this task. | E7: =COUNTIF($A:$A,$A7) -> 5
A8: TaskTier | B8: 2 | C8: TIER_CORE | D8: Base requirements only. | E8: =COUNTIF($A:$A,$A8) -> 5
A9: TaskTier | B9: 3 | C9: TIER_ADVANCED | D9: Core plus advanced. | E9: =COUNTIF($A:$A,$A9) -> 5
A10: TaskTier | B10: 4 | C10: TIER_DISRUPTIVE | D10: Core plus advanced plus disruptive. | E10: =COUNTIF($A:$A,$A10) -> 5
A11: BeaconState | B11: 0 | C11: BEACON_STATE_UNKNOWN | D11: Never send. | E11: =COUNTIF($A:$A,$A11) -> 6
A12: BeaconState | B12: 1 | C12: BEACON_STATE_OFF | D12: Not part of the safe route. | E12: =COUNTIF($A:$A,$A12) -> 6
A13: BeaconState | B13: 2 | C13: BEACON_STATE_FLASHING_RED | D13: Pass on the starboard side. | E13: =COUNTIF($A:$A,$A13) -> 6
... A17: Color | B17: 0 | C17: COLOR_UNKNOWN | D17: Never send. | E17: =COUNTIF($A:$A,$A17) -> 5
A18: Color | B18: 1 | C18: COLOR_RED | E18: =COUNTIF($A:$A,$A18) -> 5
A19: Color | B19: 2 | C19: COLOR_GREEN | E19: =COUNTIF($A:$A,$A19) -> 5
A20: Color | B20: 3 | C20: COLOR_BLUE | E20: =COUNTIF($A:$A,$A20) -> 5
A21: Color | B21: 4 | C21: COLOR_ANY | D21: Any tin is acceptable. Used at Advanced tier. | E21: =COUNTIF($A:$A,$A21) -> 5
A22: FlightPhase | B22: 0 | C22: FLIGHT_PHASE_UNKNOWN | D22: Never send from Ekko. Surface and underwater vehicles leave it here. | E22: =COUNTIF($A:$A,$A22) -> 3
A23: FlightPhase | B23: 1 | C23: FLIGHT_PHASE_GROUNDED | D23: On the ground. | E23: =COUNTIF($A:$A,$A23) -> 3
A24: FlightPhase | B24: 2 | C24: FLIGHT_PHASE_AIRBORNE | D24: In flight. | E24: =COUNTIF($A:$A,$A24) -> 3
A25: PipelineSegmentStatus | B25: 0 | C25: PIPELINE_SEGMENT_UNKNOWN | D25: Never send. | E25: =COUNTIF($A:$A,$A25) -> 3
A26: PipelineSegmentStatus | B26: 1 | C26: PIPELINE_SEGMENT_INTACT | D26: Green light — functional. | E26: =COUNTIF($A:$A,$A26) -> 3
A27: PipelineSegmentStatus | B27: 2 | C27: PIPELINE_SEGMENT_DAMAGED | D27: Red light — needs repair. | E27: =COUNTIF($A:$A,$A27) -> 3
A28: RxTask | B28: 0 | C28: TASK_UNKNOWN | D28: Never send. NOT a stand-down signal — it also appears during a mode change. | E28: =COUNTIF($A:$A,$A28) -> 6
A29: RxTask | B29: 1 | C29: TASK_NONE | D29: Deliberately idle. This is how a vehicle stands down from a task. | E29: =COUNTIF($A:$A,$A29) -> 6
A30: RxTask | B30: 2 | C30: TASK_SAFE_PASSAGE | D30: Task 1. | E30: =COUNTIF($A:$A,$A30) -> 6
A31: RxTask | B31: 3 | C31: TASK_INFRA_SURVEY_REPAIR | D31: Task 2. | E31: =COUNTIF($A:$A,$A31) -> 6
A32: RxTask | B32: 4 | C32: TASK_COORDINATED_LOGISTICS | D32: Task 3. | E32: =COUNTIF($A:$A,$A32) -> 6
... A37: VehicleType | B37: 3 | C37: TYPE_UAV | D37: Ekko. | E37: =COUNTIF($A:$A,$A37) -> 4
